Traceback (most recent call last):
  File "/home/ubuntu/miniconda/lib/python3.9/site-packages/fsspec/registry.py", line 219, in get_filesystem_class
    register_implementation(protocol, _import_class(bit["class"]))
  File "/home/ubuntu/miniconda/lib/python3.9/site-packages/fsspec/registry.py", line 242, in _import_class
    mod = importlib.import_module(mod)
  File "/home/ubuntu/miniconda/lib/python3.9/importlib/__init__.py", line 127, in import_module
    return _bootstrap._gcd_import(name[level:], package, level)
  File "<frozen importlib._bootstrap>", line 1030, in _gcd_import
  File "<frozen importlib._bootstrap>", line 1007, in _find_and_load
  File "<frozen importlib._bootstrap>", line 984, in _find_and_load_unlocked
ModuleNotFoundError: No module named 's3fs'

The above exception was the direct cause of the following exception:

Traceback (most recent call last):
  File "/home/ubuntu/dynamic/aws/worker_clogit.py", line 12, in <module>
    workers = pd.read_csv("s3://ipsos-dvd/dyn/data/dwomes_dense_csv/part-00000-6f343b3a-9ce4-47de-98a1-c810502cbb60-c000.csv",
  File "/home/ubuntu/miniconda/lib/python3.9/site-packages/pandas/util/_decorators.py", line 311, in wrapper
    return func(*args, **kwargs)
  File "/home/ubuntu/miniconda/lib/python3.9/site-packages/pandas/io/parsers/readers.py", line 680, in read_csv
    return _read(filepath_or_buffer, kwds)
  File "/home/ubuntu/miniconda/lib/python3.9/site-packages/pandas/io/parsers/readers.py", line 575, in _read
    parser = TextFileReader(filepath_or_buffer, **kwds)
  File "/home/ubuntu/miniconda/lib/python3.9/site-packages/pandas/io/parsers/readers.py", line 933, in __init__
    self._engine = self._make_engine(f, self.engine)
  File "/home/ubuntu/miniconda/lib/python3.9/site-packages/pandas/io/parsers/readers.py", line 1217, in _make_engine
    self.handles = get_handle(  # type: ignore[call-overload]
  File "/home/ubuntu/miniconda/lib/python3.9/site-packages/pandas/io/common.py", line 670, in get_handle
    ioargs = _get_filepath_or_buffer(
  File "/home/ubuntu/miniconda/lib/python3.9/site-packages/pandas/io/common.py", line 385, in _get_filepath_or_buffer
    file_obj = fsspec.open(
  File "/home/ubuntu/miniconda/lib/python3.9/site-packages/fsspec/core.py", line 462, in open
    return open_files(
  File "/home/ubuntu/miniconda/lib/python3.9/site-packages/fsspec/core.py", line 294, in open_files
    fs, fs_token, paths = get_fs_token_paths(
  File "/home/ubuntu/miniconda/lib/python3.9/site-packages/fsspec/core.py", line 632, in get_fs_token_paths
    cls = get_filesystem_class(protocol)
  File "/home/ubuntu/miniconda/lib/python3.9/site-packages/fsspec/registry.py", line 221, in get_filesystem_class
    raise ImportError(bit["err"]) from e
ImportError: Install s3fs to access S3
/home/ubuntu/miniconda/envs/fdr/lib/python3.9/site-packages/statsmodels/discrete/conditional_models.py:80: UserWarning: Dropped 775 groups and 21266 observations for having no within-group variance
  warnings.warn(msg)
/home/ubuntu/miniconda/envs/fdr/lib/python3.9/site-packages/statsmodels/discrete/conditional_models.py:266: RuntimeWarning: overflow encountered in exp
  exb = np.exp(np.dot(self._exog_grp[grp], params) + ofs)
/home/ubuntu/miniconda/envs/fdr/lib/python3.9/site-packages/statsmodels/discrete/conditional_models.py:296: RuntimeWarning: overflow encountered in exp
  exb = np.exp(np.dot(ex, params) + ofs)
/home/ubuntu/miniconda/envs/fdr/lib/python3.9/site-packages/statsmodels/discrete/conditional_models.py:317: RuntimeWarning: invalid value encountered in multiply
  d = c * h * ex[t - 1, :]
/home/ubuntu/miniconda/envs/fdr/lib/python3.9/site-packages/statsmodels/discrete/conditional_models.py:319: RuntimeWarning: invalid value encountered in scalar multiply
  u, v = a + c * h, b + d + e * h
/home/ubuntu/miniconda/envs/fdr/lib/python3.9/site-packages/statsmodels/base/model.py:595: HessianInversionWarning: Inverting hessian failed, no bse or cov_params available
  warnings.warn('Inverting hessian failed, no bse or cov_params '
Traceback (most recent call last):
  File "/home/ubuntu/dynamic/aws/worker_clogit.py", line 42, in <module>
    res = mdl.fit(maxiter=5000, method="lbfgs")
  File "/home/ubuntu/miniconda/envs/fdr/lib/python3.9/site-packages/statsmodels/discrete/conditional_models.py", line 125, in fit
    crslt = ConditionalResults(self, rslt.params, rslt.cov_params(), 1)
  File "/home/ubuntu/miniconda/envs/fdr/lib/python3.9/site-packages/statsmodels/base/model.py", line 1515, in cov_params
    raise ValueError('need covariance of parameters for computing '
ValueError: need covariance of parameters for computing (unnormalized) covariances
/home/ubuntu/miniconda/envs/fdr/lib/python3.9/site-packages/statsmodels/discrete/conditional_models.py:80: UserWarning: Dropped 775 groups and 21266 observations for having no within-group variance
  warnings.warn(msg)
/home/ubuntu/miniconda/envs/fdr/lib/python3.9/site-packages/statsmodels/discrete/conditional_models.py:266: RuntimeWarning: overflow encountered in exp
  exb = np.exp(np.dot(self._exog_grp[grp], params) + ofs)
/home/ubuntu/miniconda/envs/fdr/lib/python3.9/site-packages/statsmodels/discrete/conditional_models.py:296: RuntimeWarning: overflow encountered in exp
  exb = np.exp(np.dot(ex, params) + ofs)
/home/ubuntu/miniconda/envs/fdr/lib/python3.9/site-packages/statsmodels/discrete/conditional_models.py:317: RuntimeWarning: invalid value encountered in multiply
  d = c * h * ex[t - 1, :]
/home/ubuntu/miniconda/envs/fdr/lib/python3.9/site-packages/statsmodels/discrete/conditional_models.py:319: RuntimeWarning: invalid value encountered in scalar multiply
  u, v = a + c * h, b + d + e * h
Traceback (most recent call last):
  File "/home/ubuntu/dynamic/aws/worker_clogit.py", line 42, in <module>
    res = mdl.fit(maxiter=5000, method="lbfgs")
  File "/home/ubuntu/miniconda/envs/fdr/lib/python3.9/site-packages/statsmodels/discrete/conditional_models.py", line 117, in fit
    rslt = super(_ConditionalModel, self).fit(
  File "/home/ubuntu/miniconda/envs/fdr/lib/python3.9/site-packages/statsmodels/base/model.py", line 584, in fit
    H = -1 * self.hessian(xopt)
  File "/home/ubuntu/miniconda/envs/fdr/lib/python3.9/site-packages/statsmodels/discrete/conditional_models.py", line 101, in hessian
    hess = approx_fprime(params, self.score)
  File "/home/ubuntu/miniconda/envs/fdr/lib/python3.9/site-packages/statsmodels/tools/numdiff.py", line 151, in approx_fprime
    grad[k, :] = (f(*((x+ei,) + args), **kwargs) - f0)/epsilon[k]
  File "/home/ubuntu/miniconda/envs/fdr/lib/python3.9/site-packages/statsmodels/discrete/conditional_models.py", line 257, in score
    score += self.score_grp(g, params)
  File "/home/ubuntu/miniconda/envs/fdr/lib/python3.9/site-packages/statsmodels/discrete/conditional_models.py", line 347, in score_grp
    d, h = self._denom_grad(grp, params, ofs)
  File "/home/ubuntu/miniconda/envs/fdr/lib/python3.9/site-packages/statsmodels/discrete/conditional_models.py", line 296, in _denom_grad
    exb = np.exp(np.dot(ex, params) + ofs)
KeyboardInterrupt
/home/ubuntu/miniconda/envs/fdr/lib/python3.9/site-packages/statsmodels/discrete/conditional_models.py:80: UserWarning: Dropped 775 groups and 21266 observations for having no within-group variance
  warnings.warn(msg)
/home/ubuntu/miniconda/envs/fdr/lib/python3.9/site-packages/statsmodels/discrete/conditional_models.py:266: RuntimeWarning: overflow encountered in exp
  exb = np.exp(np.dot(self._exog_grp[grp], params) + ofs)
/home/ubuntu/miniconda/envs/fdr/lib/python3.9/site-packages/statsmodels/discrete/conditional_models.py:296: RuntimeWarning: overflow encountered in exp
  exb = np.exp(np.dot(ex, params) + ofs)
/home/ubuntu/miniconda/envs/fdr/lib/python3.9/site-packages/statsmodels/discrete/conditional_models.py:317: RuntimeWarning: invalid value encountered in multiply
  d = c * h * ex[t - 1, :]
/home/ubuntu/miniconda/envs/fdr/lib/python3.9/site-packages/statsmodels/discrete/conditional_models.py:319: RuntimeWarning: invalid value encountered in scalar multiply
  u, v = a + c * h, b + d + e * h
/home/ubuntu/miniconda/envs/fdr/lib/python3.9/site-packages/statsmodels/discrete/conditional_models.py:80: UserWarning: Dropped 775 groups and 21266 observations for having no within-group variance
  warnings.warn(msg)
/home/ubuntu/miniconda/envs/fdr/lib/python3.9/site-packages/statsmodels/discrete/conditional_models.py:266: RuntimeWarning: overflow encountered in exp
  exb = np.exp(np.dot(self._exog_grp[grp], params) + ofs)
/home/ubuntu/miniconda/envs/fdr/lib/python3.9/site-packages/statsmodels/discrete/conditional_models.py:296: RuntimeWarning: overflow encountered in exp
  exb = np.exp(np.dot(ex, params) + ofs)
/home/ubuntu/miniconda/envs/fdr/lib/python3.9/site-packages/statsmodels/discrete/conditional_models.py:317: RuntimeWarning: invalid value encountered in multiply
  d = c * h * ex[t - 1, :]
/home/ubuntu/miniconda/envs/fdr/lib/python3.9/site-packages/statsmodels/discrete/conditional_models.py:319: RuntimeWarning: invalid value encountered in scalar multiply
  u, v = a + c * h, b + d + e * h
